Workbook

Sheet Exemple BH_V2
A1: CODE | B1: TRIAL | C1: PARAMETER | D1: 0 | E1: 1 | F1: 2 | G1: 3 | H1: 4 | I1: 5 | J1: 6 | K1: 7 | L1: 8 | M1: 9 | N1: 10 | O1: 11 | P1: 12 | Q1: 13 | R1: 14 | S1: 15 | T1: 16 | U1: 17 | V1: 18 | W1: 19 | X1: 20 | Y1: 21 | Z1: 22 | AA1: 23 | AB1: 24 | AC1: 25 | AD1: 26 | AE1: 27 | AF1: 28 | AG1: 29 | AH1: 30 | AI1: 31 | AJ1: 32 | AK1: 33 | AL1: 34 | AM1: 35 | AN1: 36 | AO1: 37 | AP1: 38 | AQ1: 39 | AR1: 40 | AS1: 41 | AT1: 42 | AU1: 43 | AV1: 44 | AW1: 45 | AX1: 46 | AY1: 47 | AZ1: 48 | BA1: 49 | BB1: 50 | BC1: 51 | BD1: 52 | BE1: 53 | BF1: 54 | BG1: 55 | BH1: 56 | BI1: 57 | BJ1: 58 | BK1: 59 | BL1: 60 | BM1: 61 | BN1: 62 | BO1: 63 | BP1: 64 | BQ1: 65 | BR1: 66 | BS1: 67 | BT1: 68 | BU1: 69 | BV1: 70 | BW1: 71 | BX1: 72 | BY1: 73 | BZ1: 74 | CA1: 75 | CB1: 76 | CC1: 77 | CD1: 78 | CE1: 79 | CF1: 80 | CG1: 81 | CH1: 82 | CI1: 83 | CJ1: 84 | CK1: 85 | CL1: 86 | CM1: 87 | CN1: 88 | CO1: 89 | CP1: 90 | CQ1: 91 | CR1: 92 | CS1: 93 | CT1: 94 | CU1: 95 | CV1: 96 | CW1: 97 | CX1: 98 | CY1: 99 | CZ1: 100 | DA1: 101 | DB1: 102 | DC1: 103 | DD1: 104 | DE1: 105 | DF1: 106 | DG1: 107 | DH1: 108 | DI1: 109 | DJ1: 110 | DK1: 111 | DL1: 112 | DM1: 113 | DN1: 114 | DO1: 115 | DP1: 116 | DQ1: 117 | DR1: 118 | DS1: 119 | DT1: 120
A2: 18 | B2: 1 | C2: DEFLATOR | D2: 1 | E2: 1.0010941 | F2: 0.99962838 | G2: 0.99948463 | H2: 0.99975926 | I2: 0.9956829 | J2: 0.98608358 | K2: 0.9733013 | L2: 0.95884773 | M2: 0.94329196 | N2: 0.92618496 | O2: 0.90863767 | P2: 0.89167494 | Q2: 0.87745895 | R2: 0.8649745 | S2: 0.85363899 | T2: 0.84188851 | U2: 0.83291749 | V2: 0.82570456 | W2: 0.81980234 | X2: 0.81328231 | Y2: 0.80827287 | Z2: 0.80284504 | AA2: 0.79744191 | AB2: 0.79329389 | AC2: 0.78839799 | AD2: 0.78358581 | AE2: 0.78015327 | AF2: 0.77804277 | AG2: 0.77561966 | AH2: 0.76908826 | AI2: 0.76240139 | AJ2: 0.75666174 | AK2: 0.75274204 | AL2: 0.74956594 | AM2: 0.74654038 | AN2: 0.74254647 | AO2: 0.73587517 | AP2: 0.72815735 | AQ2: 0.71991219 | AR2: 0.71033531 | AS2: 0.69975291 | AT2: 0.69248607 | AU2: 0.68691743 | AV2: 0.67871461 | AW2: 0.67096399 | AX2: 0.66397374 | AY2: 0.65395371 | AZ2: 0.64484537 | BA2: 0.63652376 | BB2: 0.63144291 | BC2: 0.62439294 | BD2: 0.61512494 | BE2: 0.60345875 | BF2: 0.58856447 | BG2: 0.57297194 | BH2: 0.55806314 | BI2: 0.54348902 | BJ2: 0.53039868 | BK2: 0.51650248 | BL2: 0.50217187 | BM2: 0.48889989 | BN2: 0.47668372 | BO2: 0.46379107 | BP2: 0.45197246 | BQ2: 0.4410039 | BR2: 0.43027652 | BS2: 0.41958486 | BT2: 0.40986575 | BU2: 0.40103722 | BV2: 0.39304507 | BW2: 0.3861654 | BX2: 0.38014393 | BY2: 0.37528953 | BZ2: 0.37250085 | CA2: 0.36891815 | CB2: 0.36424715 | CC2: 0.35955972 | CD2: 0.35464168 | CE2: 0.34801374 | CF2: 0.34119156 | CG2: 0.33516337 | CH2: 0.32924351 | CI2: 0.32320591 | CJ2: 0.31803475 | CK2: 0.3123978 | CL2: 0.30652875 | CM2: 0.30191245 | CN2: 0.29761866 | CO2: 0.29309235 | CP2: 0.28872496 | CQ2: 0.28634888 | CR2: 0.28441273 | CS2: 0.28161143 | CT2: 0.27803702 | CU2: 0.27386079 | CV2: 0.26929402 | CW2: 0.26382515 | CX2: 0.25814313 | CY2: 0.2516882 | CZ2: 0.24495265 | DA2: 0.23870148 | DB2: 0.23248277 | DC2: 0.22655829 | DD2: 0.22166726 | DE2: 0.2169402 | DF2: 0.21314569 | DG2: 0.20945607 | DH2: 0.20503343 | DI2: 0.20102327 | DJ2: 0.19713292 | DK2: 0.19310838 | DL2: 0.18936232 | DM2: 0.18537238 | DN2: 0.18068072 | DO2: 0.17588822 | DP2: 0.17117757 | DQ2: 0.16642862 | DR2: 0.16147831 | DS2: 0.15617376 | DT2: 0.15168478
A3: 0 | B3: 1 | C3: ZC_1 | D3: 1.0016623 | E3: 1.001471 | F3: 1.0012205 | G3: 0.99851264 | H3: 0.99580476 | I3: 0.98416337 | J3: 0.97252197 | K3: 0.97048214 | L3: 0.96844231 | M3: 0.96594474 | N3: 0.96344717 | O3: 0.96278986 | P3: 0.96213255 | Q3: 0.96724475 | R3: 0.97235696 | S3: 0.97468001 | T3: 0.97700306 | U3: 0.98337115 | V3: 0.98973925 | W3: 0.98955314 | X3: 0.98936704 | Y3: 0.98543799 | Z3: 0.98150894 | AA3: 0.98505906 | AB3: 0.98860919 | AC3: 0.9900223 | AD3: 0.99143541 | AE3: 0.99366715 | AF3: 0.99589889 | AG3: 0.98893635 | AH3: 0.98197381 | AI3: 0.98564249 | AJ3: 0.98931117 | AK3: 0.98980808 | AL3: 0.990305 | AM3: 0.98569922 | AN3: 0.98109345 | AO3: 0.97774894 | AP3: 0.97440442 | AQ3: 0.97067967 | AR3: 0.96695492 | AS3: 0.97550472 | AT3: 0.98405452 | AU3: 0.9811135 | AV3: 0.97817248 | AW3: 0.97649856 | AX3: 0.97482463 | AY3: 0.97264979 | AZ3: 0.97047494 | BA3: 0.97662424 | BB3: 0.98277353 | BC3: 0.97284214 | BD3: 0.96291075 | BE3: 0.95397943 | BF3: 0.94504811 | BG3: 0.94743782 | BH3: 0.94982753 | BI3: 0.94874264 | BJ3: 0.94765775 | BK3: 0.94668339 | BL3: 0.94570904 | BM3: 0.94840809 | BN3: 0.95110714 | BO3: 0.94960836 | BP3: 0.94810958 | BQ3: 0.94964661 | BR3: 0.95118363 | BS3: 0.9516832 | BT3: 0.95218278 | BU3: 0.95663588 | BV3: 0.96108899 | BW3: 0.96512899 | BX3: 0.969169 | BY3: 0.97653336 | BZ3: 0.98389772 | CA3: 0.97858902 | CB3: 0.97328032 | CC3: 0.97107809 | CD3: 0.96887585 | CE3: 0.96362124 | CF3: 0.95836663 | CG3: 0.95991775 | CH3: 0.96146888 | CI3: 0.96568574 | CJ3: 0.9699026 | CK3: 0.96755645 | CL3: 0.9652103 | CM3: 0.96763562 | CN3: 0.97006093 | CO3: 0.97400524 | CP3: 0.97794954 | CQ3: 0.98058792 | CR3: 0.9832263 | CS3: 0.97580792 | CT3: 0.96838955 | CU3: 0.96520592 | CV3: 0.96202229 | CW3: 0.95743814 | CX3: 0.95285398 | CY3: 0.95126902 | CZ3: 0.94968406 | DA3: 0.94898597 | DB3: 0.94828789 | DC3: 0.95384332 | DD3: 0.95939875 | DE3: 0.9630709 | DF3: 0.96674305 | DG3: 0.9622728 | DH3: 0.95780256 | DI3: 0.95788687 | DJ3: 0.95797119 | DK3: 0.96115034 | DL3: 0.96432949 | DM3: 0.95592877 | DN3: 0.94752805 | DO3: 0.94727171 | DP3: 0.94701537 | DQ3: 0.94091323 | DR3: 0.93481108 | DS3: 0.94011401 | DT3: 0.94541693
A4: 0 | B4: 1 | C4: ZC_2 | D4: 1.002568 | E4: 1.0019066 | F4: 1.0011897 | G4: 0.9952111 | H4: 0.98923251 | I4: 0.96645162 | J4: 0.94367073 | K4: 0.93942258 | L4: 0.93517444 | M4: 0.93043733 | N4: 0.92570022 | O4: 0.92445305 | P4: 0.92320587 | Q4: 0.93329727 | R4: 0.94338868 | S4: 0.94811393 | T4: 0.95283917 | U4: 0.96536723 | V4: 0.97789529 | W4: 0.97770273 | X4: 0.97751017 | Y4: 0.96977128 | Z4: 0.9620324 | AA4: 0.96946785 | AB4: 0.9769033 | AC4: 0.98008742 | AD4: 0.98327155 | AE4: 0.98775744 | AF4: 0.99224333 | AG4: 0.97827041 | AH4: 0.9642975 | AI4: 0.97071636 | AJ4: 0.97713523 | AK4: 0.97779144 | AL4: 0.97844766 | AM4: 0.96888332 | AN4: 0.95931898 | AO4: 0.95258266 | AP4: 0.94584634 | AQ4: 0.93892462 | AR4: 0.93200289 | AS4: 0.94839545 | AT4: 0.96478801 | AU4: 0.95952944 | AV4: 0.95427088 | AW4: 0.95075453 | AX4: 0.94723818 | AY4: 0.94346611 | AZ4: 0.93969405 | BA4: 0.95145701 | BB4: 0.96321997 | BC4: 0.9441824 | BD4: 0.92514484 | BE4: 0.90824726 | BF4: 0.89134969 | BG4: 0.89596652 | BH4: 0.90058334 | BI4: 0.89855128 | BJ4: 0.89651921 | BK4: 0.89455684 | BL4: 0.89259447 | BM4: 0.8978133 | BN4: 0.90303213 | BO4: 0.90037337 | BP4: 0.89771462 | BQ4: 0.90032162 | BR4: 0.90292862 | BS4: 0.90403108 | BT4: 0.90513353 | BU4: 0.91359488 | BV4: 0.92205623 | BW4: 0.92980218 | BX4: 0.93754813 | BY4: 0.95163352 | BZ4: 0.96571892 | CA4: 0.95580065 | CB4: 0.94588239 | CC4: 0.94109713 | CD4: 0.93631188 | CE4: 0.92684025 | CF4: 0.91736862 | CG4: 0.91995981 | CH4: 0.922551 | CI4: 0.93062518 | CJ4: 0.93869935 | CK4: 0.93441075 | CL4: 0.93012215 | CM4: 0.93457991 | CN4: 0.93903767 | CO4: 0.9468804 | CP4: 0.95472313 | CQ4: 0.95941166 | CR4: 0.96410019 | CS4: 0.95020344 | CT4: 0.93630669 | CU4: 0.93000209 | CV4: 0.92369749 | CW4: 0.91499978 | CX4: 0.90630207 | CY4: 0.90308345 | CZ4: 0.89986484 | DA4: 0.89901654 | DB4: 0.89816824 | DC4: 0.90845619 | DD4: 0.91874413 | DE4: 0.92550628 | DF4: 0.93226843 | DG4: 0.92424654 | DH4: 0.91622465 | DI4: 0.91588706 | DJ4: 0.91554948 | DK4: 0.92186429 | DL4: 0.92817909 | DM4: 0.91226237 | DN4: 0.89634565 | DO4: 0.89560358 | DP4: 0.8948615 | DQ4: 0.88373758 | DR4: 0.87261366 | DS4: 0.88223409 | DT4: 0.89185452
A5: 0 | B5: 1 | C5: ZC_3 | D5: 1.0021081 | E5: 1.0005469 | F5: 0.99875115 | G5: 0.98951368 | H5: 0.98027621 | I5: 0.94667303 | J5: 0.91306985 | K5: 0.90684479 | L5: 0.90061973 | M5: 0.89386575 | N5: 0.88711177 | O5: 0.88561257 | P5: 0.88411337 | Q5: 0.89895866 | R5: 0.91380396 | S5: 0.92086052 | T5: 0.92791709 | U5: 0.94643598 | V5: 0.96495486 | W5: 0.96469869 | X5: 0.96444251 | Y5: 0.95356369 | Z5: 0.94268486 | AA5: 0.95422476 | AB5: 0.96576465 | AC5: 0.97074025 | AD5: 0.97571586 | AE5: 0.98210722 | AF5: 0.98849859 | AG5: 0.96702296 | AH5: 0.94554734 | AI5: 0.95426708 | AJ5: 0.96298682 | AK5: 0.96322597 | AL5: 0.96346512 | AM5: 0.94896839 | AN5: 0.93447166 | AO5: 0.92483255 | AP5: 0.91519344 | AQ5: 0.90525048 | AR5: 0.89530751 | AS5: 0.91935903 | AT5: 0.94341055 | AU5: 0.93571644 | AV5: 0.92802233 | AW5: 0.92321033 | AX5: 0.91839833 | AY5: 0.913029 | AZ5: 0.90765968 | BA5: 0.92473147 | BB5: 0.94180326 | BC5: 0.91438333 | BD5: 0.8869634 | BE5: 0.86316016 | BF5: 0.83935691 | BG5: 0.84591956 | BH5: 0.85248222 | BI5: 0.84949751 | BJ5: 0.8465128 | BK5: 0.84382702 | BL5: 0.84114124 | BM5: 0.84871344 | BN5: 0.85628564 | BO5: 0.85234051 | BP5: 0.84839539 | BQ5: 0.8520868 | BR5: 0.85577821 | BS5: 0.85742391 | BT5: 0.85906961 | BU5: 0.87110932 | BV5: 0.88314902 | BW5: 0.89409319 | BX5: 0.90503737 | BY5: 0.92573762 | BZ5: 0.94643788 | CA5: 0.9316789 | CB5: 0.91691993 | CC5: 0.91031939 | CD5: 0.90371886 | CE5: 0.89008805 | CF5: 0.87645724 | CG5: 0.87997974 | CH5: 0.88350224 | CI5: 0.8952789 | CJ5: 0.90705557 | CK5: 0.90080901 | CL5: 0.89456246 | CM5: 0.90108716 | CN5: 0.90761187 | CO5: 0.91863594 | CP5: 0.92966001 | CQ5: 0.93671311 | CR5: 0.94376621 | CS5: 0.92365058 | CT5: 0.90353496 | CU5: 0.89440543 | CV5: 0.88527589 | CW5: 0.87269724 | CX5: 0.86011859 | CY5: 0.85590875 | CZ5: 0.85169891 | DA5: 0.85051359 | DB5: 0.84932826 | DC5: 0.86356172 | DD5: 0.87779518 | DE5: 0.88782879 | DF5: 0.89786241 | DG5: 0.88616337 | DH5: 0.87446434 | DI5: 0.87399276 | DJ5: 0.87352117 | DK5: 0.88265936 | DL5: 0.89179756 | DM5: 0.8689626 | DN5: 0.84612765 | DO5: 0.84521169 | DP5: 0.84429573 | DQ5: 0.82862936 | DR5: 0.81296298 | DS5: 0.82678479 | DT5: 0.84060659
A6: 0 | B6: 1 | C6: ZC_4 | D6: 0.99947957 | E6: 0.99679274 | F6: 0.99386545 | G6: 0.98114499 | H6: 0.96842454 | I6: 0.92477099 | J6: 0.88111745 | K6: 0.87311261 | L6: 0.86510777 | M6: 0.85681924 | N6: 0.84853072 | O6: 0.84702073 | P6: 0.84551075 | Q6: 0.86475232 | R6: 0.88399389 | S6: 0.89335856 | T6: 0.90272322 | U6: 0.92682631 | V6: 0.95092941 | W6: 0.95109796 | X6: 0.95126651 | Y6: 0.93778376 | Z6: 0.92430102 | AA6: 0.93984324 | AB6: 0.95538547 | AC6: 0.96180919 | AD6: 0.96823291 | AE6: 0.97571287 | AF6: 0.98319284 | AG6: 0.95423297 | AH6: 0.9252731 | AI6: 0.9356012 | AJ6: 0.94592929 | AK6: 0.94550808 | AL6: 0.94508687 | AM6: 0.92623182 | AN6: 0.90737678 | AO6: 0.89497877 | AP6: 0.88258075 | AQ6: 0.87033341 | AR6: 0.85808606 | AS6: 0.8888594 | AT6: 0.91963273 | AU6: 0.91009112 | AV6: 0.9005495 | AW6: 0.89442275 | AX6: 0.88829599 | AY6: 0.88157523 | AZ6: 0.87485446 | BA6: 0.89679704 | BB6: 0.91873962 | BC6: 0.88380186 | BD6: 0.8488641 | BE6: 0.8190399 | BF6: 0.78921569 | BG6: 0.79733155 | BH6: 0.8054474 | BI6: 0.80176804 | BJ6: 0.79808867 | BK6: 0.79492778 | BL6: 0.79176689 | BM6: 0.80111549 | BN6: 0.81046409 | BO6: 0.80554634 | BP6: 0.80062859 | BQ6: 0.8052702 | BR6: 0.80991182 | BS6: 0.81204362 | BT6: 0.81417542 | BU6: 0.82921724 | BV6: 0.84425907 | BW6: 0.85841988 | BX6: 0.87258069 | BY6: 0.89886028 | BZ6: 0.92513987 | CA6: 0.90645035 | CB6: 0.88776084 | CC6: 0.87916193 | CD6: 0.87056302 | CE6: 0.8532109 | CF6: 0.83585878 | CG6: 0.84039732 | CH6: 0.84493585 | CI6: 0.85986499 | CJ6: 0.87479413 | CK6: 0.86698342 | CL6: 0.85917271 | CM6: 0.86716856 | CN6: 0.87516441 | CO6: 0.88952475 | CP6: 0.90388508 | CQ6: 0.91293194 | CR6: 0.92197881 | CS6: 0.89614502 | CT6: 0.87031123 | CU6: 0.85842776 | CV6: 0.8465443 | CW6: 0.8309744 | CX6: 0.81540449 | CY6: 0.81013884 | CZ6: 0.80487318 | DA6: 0.80318202 | DB6: 0.80149085 | DC6: 0.81961914 | DD6: 0.83774743 | DE6: 0.8502448 | DF6: 0.86274217 | DG6: 0.84800099 | DH6: 0.83325981 | DI6: 0.8326772 | DJ6: 0.8320946 | DK6: 0.84349658 | DL6: 0.85489855 | DM6: 0.82623551 | DN6: 0.79757246 | DO6: 0.79626995 | DP6: 0.79496743 | DQ6: 0.77594273 | DR6: 0.75691803 | DS6: 0.7735658 | DT6: 0.79021357
A7: 0 | B7: 1 | C7: ZC_5 | D7: 0.99445428 | E7: 0.99034668 | F7: 0.98597933 | G7: 0.96997465 | H7: 0.95396997 | I7: 0.90104653 | J7: 0.84812309 | K7: 0.83878987 | L7: 0.82945664 | M7: 0.82001548 | N7: 0.81057432 | O7: 0.80915228 | P7: 0.80773025 | Q7: 0.83107145 | R7: 0.85441265 | S7: 0.86584529 | T7: 0.87727794 | U7: 0.90709037 | V7: 0.9369028 | W7: 0.93786637 | X7: 0.93882993 | Y7: 0.92293179 | Z7: 0.90703365 | AA7: 0.92613228 | AB7: 0.9452309 | AC7: 0.95230618 | AD7: 0.95938145 | AE7: 0.96758922 | AF7: 0.975797 | AG7: 0.93920134 | AH7: 0.90260569 | AI7: 0.91415884 | AJ7: 0.925712 | AK7: 0.9248988 | AL7: 0.9240856 | AM7: 0.90111409 | AN7: 0.87814258 | AO7: 0.86366558 | AP7: 0.84918857 | AQ7: 0.83465593 | AR7: 0.82012328 | AS7: 0.85733591 | AT7: 0.89454854 | AU7: 0.88319111 | AV7: 0.87183368 | AW7: 0.86461322 | AX7: 0.85739275 | AY7: 0.8494495 | AZ7: 0.84150626 | BA7: 0.8680097 | BB7: 0.89451315 | BC7: 0.852787 | BD7: 0.81106084 | BE7: 0.77593108 | BF7: 0.74080132 | BG7: 0.75035046 | BH7: 0.7598996 | BI7: 0.75576727 | BJ7: 0.75163493 | BK7: 0.74783695 | BL7: 0.74403896 | BM7: 0.75502946 | BN7: 0.76601997 | BO7: 0.76028249 | BP7: 0.75454501 | BQ7: 0.76001101 | BR7: 0.765477 | BS7: 0.76789031 | BT7: 0.77030361 | BU7: 0.78827519 | BV7: 0.80624676 | BW7: 0.82279704 | BX7: 0.83934732 | BY7: 0.87126059 | BZ7: 0.90317386 | CA7: 0.88052404 | CB7: 0.85787421 | CC7: 0.84747168 | CD7: 0.83706915 | CE7: 0.8166011 | CF7: 0.79613305 | CG7: 0.80139816 | CH7: 0.80666327 | CI7: 0.82459916 | CJ7: 0.84253505 | CK7: 0.83294485 | CL7: 0.82335465 | CM7: 0.83305955 | CN7: 0.84276445 | CO7: 0.85996711 | CP7: 0.87716977 | CQ7: 0.88805991 | CR7: 0.89895005 | CS7: 0.86768483 | CT7: 0.83641961 | CU7: 0.82250915 | CV7: 0.8085987 | CW7: 0.790229 | CX7: 0.7718593 | CY7: 0.76548483 | CZ7: 0.75911036 | DA7: 0.75739931 | DB7: 0.75568826 | DC7: 0.77676431 | DD7: 0.79784035 | DE7: 0.81273701 | DF7: 0.82763367 | DG7: 0.81021455 | DH7: 0.79279542 | DI7: 0.79188583 | DJ7: 0.79097624 | DK7: 0.80460158 | DL7: 0.81822691 | DM7: 0.78427913 | DN7: 0.75033135 | DO7: 0.74916299 | DP7: 0.74799462 | DQ7: 0.72551641 | DR7: 0.70303819 | DS7: 0.72269902 | DT7: 0.74235985
A8: 0 | B8: 1 | C8: ZC_6 | D8: 0.98650877 | E8: 0.98106034 | F8: 0.97535236 | G8: 0.9562465 | H8: 0.93714064 | I8: 0.87600981 | J8: 0.81487898 | K8: 0.80457231 | L8: 0.79426563 | M8: 0.78390678 | N8: 0.77354792 | O8: 0.77234624 | P8: 0.77114455 | Q8: 0.79810453 | R8: 0.8250645 | S8: 0.83882023 | T8: 0.85257595 | U8: 0.88813979 | V8: 0.92370362 | W8: 0.92550466 | X8: 0.9273057 | Y8: 0.90882609 | Z8: 0.89034648 | AA8: 0.91211878 | AB8: 0.93389107 | AC8: 0.94127458 | AD8: 0.94865809 | AE8: 0.95698253 | AF8: 0.96530696 | AG8: 0.92132782 | AH8: 0.87734868 | AI8: 0.89022672 | AJ8: 0.90310475 | AK8: 0.90181334 | AL8: 0.90052194 | AM8: 0.87422239 | AN8: 0.84792285 | AO8: 0.83135784 | AP8: 0.81479282 | AQ8: 0.79861129 | AR8: 0.78242976 | AS8: 0.82527788 | AT8: 0.868126 | AU8: 0.85522222 | AV8: 0.84231844 | AW8: 0.83411066 | AX8: 0.82590288 | AY8: 0.81698731 | AZ8: 0.80807174 | BA8: 0.83870582 | BB8: 0.86933991 | BC8: 0.82141805 | BD8: 0.7734962 | BE8: 0.73397223 | BF8: 0.69444826 | BG8: 0.70532543 | BH8: 0.7162026 | BI8: 0.71146843 | BJ8: 0.70673426 | BK8: 0.70252658 | BL8: 0.6983189 | BM8: 0.71069841 | BN8: 0.72307792 | BO8: 0.71666149 | BP8: 0.71024506 | BQ8: 0.71627745 | BR8: 0.72230983 | BS8: 0.725249 | BT8: 0.72818816 | BU8: 0.74825196 | BV8: 0.76831577 | BW8: 0.78744767 | BX8: 0.80657957 | BY8: 0.84328334 | BZ8: 0.87998711 | CA8: 0.85372989 | CB8: 0.82747266 | CC8: 0.81563957 | CD8: 0.80380649 | CE8: 0.78044272 | CF8: 0.75707896 | CG8: 0.76315512 | CH8: 0.76923128 | CI8: 0.78945891 | CJ8: 0.80968655 | CK8: 0.79889499 | CL8: 0.78810344 | CM8: 0.79914681 | CN8: 0.81019018 | CO8: 0.82995688 | CP8: 0.84972358 | CQ8: 0.8620771 | CR8: 0.87443062 | CS8: 0.83868544 | CT8: 0.80294026 | CU8: 0.78705419 | CV8: 0.77116812 | CW8: 0.75019193 | CX8: 0.72921573 | CY8: 0.722295 | CZ8: 0.71537428 | DA8: 0.71326727 | DB8: 0.71116027 | DC8: 0.73494186 | DD8: 0.75872345 | DE8: 0.77572624 | DF8: 0.79272904 | DG8: 0.77275343 | DH8: 0.75277783 | DI8: 0.75180333 | DJ8: 0.75082882 | DK8: 0.76615518 | DL8: 0.78148153 | DM8: 0.7434623 | DN8: 0.70544307 | DO8: 0.7037436 | DP8: 0.70204414 | DQ8: 0.67738008 | DR8: 0.65271603 | DS8: 0.67441959 | DT8: 0.69612316
A9: 0 | B9: 1 | C9: ZC_7 | D9: 0.97564521 | E9: 0.96916105 | F9: 0.96218282 | G9: 0.94045906 | H9: 0.9187353 | I9: 0.85035208 | J9: 0.78196887 | K9: 0.77090136 | L9: 0.75983386 | M9: 0.74881448 | N9: 0.73779509 | O9: 0.73675121 | P9: 0.73570732 | Q9: 0.76628593 | R9: 0.79686454 | S9: 0.81309684 | T9: 0.82932913 | U9: 0.87041163 | V9: 0.91149413 | W9: 0.91382807 | X9: 0.916162 | Y9: 0.89453226 | Z9: 0.87290251 | AA9: 0.89689246 | AB9: 0.92088241 | AC9: 0.9279941 | AD9: 0.93510578 | AE9: 0.94325077 | AF9: 0.95139575 | AG9: 0.90083295 | AH9: 0.85027016 | AI9: 0.86422249 | AJ9: 0.87817483 | AK9: 0.87685699 | AL9: 0.87553914 | AM9: 0.84601 | AN9: 0.81648086 | AO9: 0.7984349 | AP9: 0.78038895 | AQ9: 0.7626809 | AR9: 0.74497285 | AS9: 0.79288364 | AT9: 0.84079443 | AU9: 0.82650019 | AV9: 0.81220596 | AW9: 0.80323647 | AX9: 0.79426699 | AY9: 0.78450521 | AZ9: 0.77474343 | BA9: 0.80894985 | BB9: 0.84315628 | BC9: 0.78987477 | BD9: 0.73659326 | BE9: 0.69351272 | BF9: 0.65043218 | BG9: 0.66219319 | BH9: 0.6739542 | BI9: 0.66883911 | BJ9: 0.66372401 | BK9: 0.65919333 | BL9: 0.65466265 | BM9: 0.66819883 | BN9: 0.68173501 | BO9: 0.67463804 | BP9: 0.66754106 | BQ9: 0.6743073 | BR9: 0.68107354 | BS9: 0.68406319 | BT9: 0.68705285 | BU9: 0.70931621 | BV9: 0.73157957 | BW9: 0.75267497 | BX9: 0.77377037 | BY9: 0.81477426 | BZ9: 0.85577816 | CA9: 0.82644574 | CB9: 0.79711332 | CC9: 0.78385091 | CD9: 0.77058849 | CE9: 0.74488767 | CF9: 0.71918685 | CG9: 0.72562832 | CH9: 0.7320698 | CI9: 0.75464581 | CJ9: 0.77722181 | CK9: 0.7652062 | CL9: 0.75319058 | CM9: 0.76540968 | CN9: 0.77762879 | CO9: 0.79947282 | CP9: 0.82131686 | CQ9: 0.83542433 | CR9: 0.84953181 | CS9: 0.80957151 | CT9: 0.76961121 | CU9: 0.75180882 | CV9: 0.73400644 | CW9: 0.71120307 | CX9: 0.6883997 | CY9: 0.68066582 | CZ9: 0.67293195 | DA9: 0.67067842 | DB9: 0.66842489 | DC9: 0.69448192 | DD9: 0.72053895 | DE9: 0.73914187 | DF9: 0.75774478 | DG9: 0.73578478 | DH9: 0.71382478 | DI9: 0.71258332 | DJ9: 0.71134186 | DK9: 0.72857476 | DL9: 0.74580766 | DM9: 0.70372101 | DN9: 0.66163436 | DO9: 0.66010847 | DP9: 0.65858258 | DQ9: 0.63179885 | DR9: 0.60501512 | DS9: 0.62831338 | DT9: 0.65161164
A10: 0 | B10: 1 | C10: ZC_8 | D10: 0.9622231 | E10: 0.95514106 | F10: 0.94726107 | G10: 0.92332252 | H10: 0.89938398 | I10: 0.82453485 | J10: 0.74968572 | K10: 0.7380936 | L10: 0.72650148 | M10: 0.71487994 | N10: 0.7032584 | O10: 0.7027178 | P10: 0.70217719 | Q10: 0.7363102 | R10: 0.7704432 | S10: 0.78903236 | T10: 0.80762151 | U10: 0.85368297 | V10: 0.89974442 | W10: 0.90188405 | X10: 0.90402368 | Y10: 0.87914416 | Z10: 0.85426464 | AA10: 0.87977575 | AB10: 0.90528685 | AC10: 0.91186014 | AD10: 0.91843342 | AE10: 0.92660881 | AF10: 0.93478419 | AG10: 0.87812191 | AH10: 0.82145963 | AI10: 0.83675063 | AJ10: 0.85204163 | AK10: 0.85045462 | AL10: 0.84886761 | AM10: 0.81683542 | AN10: 0.78480322 | AO10: 0.7653735 | AP10: 0.74594377 | AQ10: 0.72702684 | AR10: 0.7081099 | AS10: 0.76042794 | AT10: 0.81274599 | AU10: 0.79733411 | AV10: 0.78192223 | AW10: 0.77229542 | AX10: 0.76266861 | AY10: 0.75206295 | AZ10: 0.74145729 | BA10: 0.77894251 | BB10: 0.81642773 | BC10: 0.75858167 | BD10: 0.70073561 | BE10: 0.65453387 | BF10: 0.60833214 | BG10: 0.62090215 | BH10: 0.63347216 | BI10: 0.62806251 | BJ10: 0.62265286 | BK10: 0.61787704 | BL10: 0.61310122 | BM10: 0.627457 | BN10: 0.64181277 | BO10: 0.63441191 | BP10: 0.62701105 | BQ10: 0.63401395 | BR10: 0.64101686 | BS10: 0.64443028 | BT10: 0.64784369 | BU10: 0.67169148 | BV10: 0.69553927 | BW10: 0.71831638 | BX10: 0.74109348 | BY10: 0.78610278 | BZ10: 0.83111208 | CA10: 0.79886049 | CB10: 0.76660891 | CC10: 0.75227036 | CD10: 0.73793181 | CE10: 0.70991597 | CF10: 0.68190014 | CG10: 0.68896624 | CH10: 0.69603234 | CI10: 0.72047383 | CJ10: 0.74491532 | CK10: 0.73184336 | CL10: 0.71877139 | CM10: 0.73181681 | CN10: 0.74486224 | CO10: 0.76892878 | CP10: 0.79299532 | CQ10: 0.80848896 | CR10: 0.8239826 | CS10: 0.78008646 | CT10: 0.73619032 | CU10: 0.7171301 | CV10: 0.69806989 | CW10: 0.67338924 | CX10: 0.64870859 | CY10: 0.64048518 | CZ10: 0.63226178 | DA10: 0.62989835 | DB10: 0.62753492 | DC10: 0.65526551 | DD10: 0.68299609 | DE10: 0.70315459 | DF10: 0.7233131 | DG10: 0.6994705 | DH10: 0.67562791 | DI10: 0.67457467 | DJ10: 0.67352144 | DK10: 0.69172902 | DL10: 0.7099366 | DM10: 0.66510511 | DN10: 0.62027362 | DO10: 0.6185174 | DP10: 0.61676117 | DQ10: 0.58834468 | DR10: 0.55992818 | DS10: 0.58462494 | DT10: 0.60932169
A11: 0 | B11: 1 | C11: ZC_9 | D11: 0.94679282 | E11: 0.93970819 | F11: 0.93121654 | G11: 0.90532289 | H11: 0.87942923 | I11: 0.79889764 | J11: 0.71836605 | K11: 0.70629132 | L11: 0.6942166 | M11: 0.68243348 | N11: 0.67065037 | O11: 0.67084016 | P11: 0.67102995 | Q11: 0.70843346 | R11: 0.74583698 | S11: 0.76638232 | T11: 0.78692767 | U11: 0.83701351 | V11: 0.88709935 | W11: 0.88875872 | X11: 0.89041809 | Y11: 0.8620131 | Z11: 0.83360812 | AA11: 0.86022314 | AB11: 0.88683817 | AC11: 0.89309933 | AD11: 0.8993605 | AE11: 0.90742147 | AF11: 0.91548244 | AG11: 0.85373185 | AH11: 0.79198126 | AI11: 0.80821188 | AJ11: 0.82444251 | AK11: 0.82297711 | AL11: 0.8215117 | AM11: 0.78718229 | AN11: 0.75285289 | AO11: 0.73233441 | AP11: 0.71181593 | AQ11: 0.69189556 | AR11: 0.67197519 | AS11: 0.72818734 | AT11: 0.78439949 | AU11: 0.76802072 | AV11: 0.75164196 | AW11: 0.74134087 | AX11: 0.73103978 | AY11: 0.71982563 | AZ11: 0.70861148 | BA11: 0.74910927 | BB11: 0.78960706 | BC11: 0.72758596 | BD11: 0.66556486 | BE11: 0.61697482 | BF11: 0.56838478 | BG11: 0.58159259 | BH11: 0.5948004 | BI11: 0.58917365 | BJ11: 0.5835469 | BK11: 0.57848346 | BL11: 0.57342001 | BM11: 0.58864486 | BN11: 0.60386971 | BO11: 0.59589902 | BP11: 0.58792834 | BQ11: 0.5954642 | BR11: 0.60300005 | BS11: 0.60652843 | BT11: 0.6100568 | BU11: 0.63518874 | BV11: 0.66032068 | BW11: 0.6846726 | BX11: 0.70902452 | BY11: 0.75740751 | BZ11: 0.80579049 | CA11: 0.77113116 | CB11: 0.73647183 | CC11: 0.72087929 | CD11: 0.70528674 | CE11: 0.6756396 | CF11: 0.64599246 | CG11: 0.65343477 | CH11: 0.66087708 | CI11: 0.68689852 | CJ11: 0.71291997 | CK11: 0.69877279 | CL11: 0.6846256 | CM11: 0.69872609 | CN11: 0.71282657 | CO11: 0.73866147 | CP11: 0.76449637 | CQ11: 0.78100851 | CR11: 0.79752065 | CS11: 0.75058171 | CT11: 0.70364278 | CU11: 0.68316098 | CV11: 0.66267919 | CW11: 0.63664227 | CX11: 0.61060536 | CY11: 0.60200399 | CZ11: 0.59340263 | DA11: 0.59078556 | DB11: 0.5881685 | DC11: 0.61740063 | DD11: 0.64663276 | DE11: 0.66788558 | DF11: 0.6891384 | DG11: 0.66413427 | DH11: 0.63913014 | DI11: 0.63765497 | DJ11: 0.63617981 | DK11: 0.65578833 | DL11: 0.67539684 | DM11: 0.62797217 | DN11: 0.5805475 | DO11: 0.57859865 | DP11: 0.57664979 | DQ11: 0.54721447 | DR11: 0.51777914 | DS11: 0.54331638 | DT11: 0.56885361
A12: 0 | B12: 1 | C12: ZC_10 | D12: 0.93039436 | E12: 0.92334566 | F12: 0.91439073 | G12: 0.88684219 | H12: 0.85929365 | I12: 0.77362745 | J12: 0.68796125 | K12: 0.67582524 | L12: 0.66368924 | M12: 0.65205072 | N12: 0.6404122 | O12: 0.64131057 | P12: 0.64220893 | Q12: 0.68236603 | R12: 0.72252312 | S12: 0.7442798 | T12: 0.76603648 | U12: 0.81956479 | V12: 0.87309311 | W12: 0.8737737 | X12: 0.87445429 | Y12: 0.84259072 | Z12: 0.81072715 | AA12: 0.83848609 | AB12: 0.86624502 | AC12: 0.87207953 | AD12: 0.87791403 | AE12: 0.8862603 | AF12: 0.89460658 | AG12: 0.82810092 | AH12: 0.76159527 | AI12: 0.77897337 | AJ12: 0.79635148 | AK12: 0.79488831 | AL12: 0.79342515 | AM12: 0.75720729 | AN12: 0.72098943 | AO12: 0.69956716 | AP12: 0.67814488 | AQ12: 0.65751067 | AR12: 0.63687646 | AS12: 0.69640096 | AT12: 0.75592546 | AU12: 0.73860911 | AV12: 0.72129276 | AW12: 0.71053079 | AX12: 0.69976882 | AY12: 0.6881707 | AZ12: 0.67657257 | BA12: 0.71944961 | BB12: 0.76232665 | BC12: 0.69687666 | BD12: 0.63142666 | BE12: 0.5810025 | BF12: 0.53057835 | BG12: 0.54427034 | BH12: 0.55796233 | BI12: 0.55208081 | BJ12: 0.54619928 | BK12: 0.54113244 | BL12: 0.53606559 | BM12: 0.55163785 | BN12: 0.5672101 | BO12: 0.55913055 | BP12: 0.55105099 | BQ12: 0.5587905 | BR12: 0.56653001 | BS12: 0.57014048 | BT12: 0.57375095 | BU12: 0.60003164 | BV12: 0.62631233 | BW12: 0.65184067 | BX12: 0.677369 | BY12: 0.72885964 | BZ12: 0.78035028 | CA12: 0.74325199 | CB12: 0.70615369 | CC12: 0.68981303 | CD12: 0.67347237 | CE12: 0.64234329 | CF12: 0.61121421 | CG12: 0.61895922 | CH12: 0.62670424 | CI12: 0.65386069 | CJ12: 0.68101715 | CK12: 0.66630516 | CL12: 0.65159317 | CM12: 0.66642628 | CN12: 0.68125939 | CO12: 0.70841559 | CP12: 0.73557179 | CQ12: 0.75338333 | CR12: 0.77119486 | CS12: 0.72124566 | CT12: 0.67129645 | CU12: 0.64981511 | CV12: 0.62833377 | CW12: 0.60123272 | CX12: 0.57413168 | CY12: 0.56508592 | CZ12: 0.55604015 | DA12: 0.55338222 | DB12: 0.55072429 | DC12: 0.58093574 | DD12: 0.61114719 | DE12: 0.63367452 | DF12: 0.65620186 | DG12: 0.62969687 | DH12: 0.60319188 | DI12: 0.60192287 | DJ12: 0.60065387 | DK12: 0.62102433 | DL12: 0.64139479 | DM12: 0.59195239 | DN12: 0.54250998 | DO12: 0.54058664 | DP12: 0.5386633 | DQ12: 0.50839447 | DR12: 0.47812565 | DS12: 0.50437137 | DT12: 0.53061708
A13: 0 | B13: 1 | C13: ZC_11 | D13: 0.91347174 | E13: 0.90643746 | F13: 0.89721476 | G13: 0.86808877 | H13: 0.83896277 | I13: 0.74907109 | J13: 0.65917941 | K13: 0.64727361 | L13: 0.63536781 | M13: 0.62392249 | N13: 0.61247717 | O13: 0.61383096 | P13: 0.61518474 | Q13: 0.65727531 | R13: 0.69936588 | S13: 0.72196079 | T13: 0.74455571 | U13: 0.80070343 | V13: 0.85685115 | W13: 0.85636199 | X13: 0.85587283 | Y13: 0.82108916 | Z13: 0.7863055 | AA13: 0.81492407 | AB13: 0.84354264 | AC13: 0.84935971 | AD13: 0.85517679 | AE13: 0.86351057 | AF13: 0.87184435 | AG13: 0.8015236 | AH13: 0.73120286 | AI13: 0.74946065 | AJ13: 0.76771844 | AK13: 0.76635006 | AL13: 0.76498168 | AM13: 0.72716838 | AN13: 0.68935509 | AO13: 0.66730167 | AP13: 0.64524825 | AQ13: 0.62407454 | AR13: 0.60290083 | AS13: 0.66507408 | AT13: 0.72724732 | AU13: 0.70925018 | AV13: 0.69125303 | AW13: 0.68023439 | AX13: 0.66921575 | AY13: 0.65710509 | AZ13: 0.64499442 | BA13: 0.69000363 | BB13: 0.73501283 | BC13: 0.66670842 | BD13: 0.598404 | BE13: 0.54664427 | BF13: 0.49488454 | BG13: 0.50882193 | BH13: 0.52275932 | BI13: 0.51689651 | BJ13: 0.51103369 | BK13: 0.50570091 | BL13: 0.50036813 | BM13: 0.51646856 | BN13: 0.53256898 | BO13: 0.524232 | BP13: 0.51589502 | BQ13: 0.52376783 | BR13: 0.53164063 | BS13: 0.5354251 | BT13: 0.53920957 | BU13: 0.56625633 | BV13: 0.5933031 | BW13: 0.61992781 | BX13: 0.64655251 | BY13: 0.70038272 | BZ13: 0.75421293 | CA13: 0.71534357 | CB13: 0.67647421 | CC13: 0.6593663 | CD13: 0.64225839 | CE13: 0.60994692 | CF13: 0.57763546 | CG13: 0.58546135 | CH13: 0.59328723 | CI13: 0.62166547 | CJ13: 0.65004371 | CK13: 0.63472524 | CL13: 0.61940676 | CM13: 0.63466351 | CN13: 0.64992025 | CO13: 0.67855088 | CP13: 0.7071815 | CQ13: 0.72573486 | CR13: 0.74428823 | CS13: 0.69197701 | CT13: 0.6396658 | CU13: 0.6173882 | CV13: 0.5951106 | CW13: 0.56704921 | CX13: 0.53898782 | CY13: 0.52976507 | CZ13: 0.52054233 | DA13: 0.51770959 | DB13: 0.51487686 | DC13: 0.54612402 | DD13: 0.57737118 | DE13: 0.60036465 | DF13: 0.62335813 | DG13: 0.59621403 | DH13: 0.56906994 | DI13: 0.56763065 | DJ13: 0.56619136 | DK13: 0.58712489 | DL13: 0.60805843 | DM13: 0.55729937 | DN13: 0.50654032 | DO13: 0.50448295 | DP13: 0.50242558 | DQ13: 0.47182204 | DR13: 0.4412185 | DS13: 0.46771869 | DT13: 0.49421888
... A481: 8 | B481: 10 | C481: PROP_TOTAL_RETURN | D481: 0 | E481: 0 | F481: -0.18256564 | G481: 0 | H481: 0.070399834 | I481: 0 | J481: 0.44142503 | K481: 0 | L481: 0.0017892965 | M481: 0 | N481: 0.19718805 | O481: 0 | P481: 0.19062456 | Q481: 0 | R481: -0.13692579 | S481: 0 | T481: -0.10136496 | U481: 0 | V481: 0.13784138 | W481: 0 | X481: 0.017423594 | Y481: 0 | Z481: 0.071447568 | AA481: 0 | AB481: -0.15567354 | AC481: 0 | AD481: -0.17527456 | AE481: 0 | AF481: -0.01814679 | AG481: 0 | AH481: -0.048922741 | AI481: 0 | AJ481: -0.092221296 | AK481: 0 | AL481: -0.21525938 | AM481: 0 | AN481: 0.087352092 | AO481: 0 | AP481: -0.11876179 | AQ481: 0 | AR481: -0.052757636 | AS481: 0 | AT481: 0.0629038 | AU481: 0 | AV481: 0.020867257 | AW481: 0 | AX481: 0.11516553 | AY481: 0 | AZ481: -0.033149879 | BA481: 0 | BB481: -0.16433016 | BC481: 0 | BD481: -0.076240221 | BE481: 0 | BF481: -0.14248177 | BG481: 0 | BH481: 0.11176595 | BI481: 0 | BJ481: -0.11422413 | BK481: 0 | BL481: -0.0028076489 | BM481: 0 | BN481: -0.13954493 | BO481: 0 | BP481: -0.11854748 | BQ481: 0 | BR481: -0.041218463 | BS481: 0 | BT481: -0.055593821 | BU481: 0 | BV481: 0.032182713 | BW481: 0 | BX481: -0.17965817 | BY481: 0 | BZ481: -0.082674659 | CA481: 0 | CB481: 0.12636789 | CC481: 0 | CD481: -0.1445577 | CE481: 0 | CF481: 0.11251565 | CG481: 0 | CH481: -0.10750173 | CI481: 0 | CJ481: -0.23399973 | CK481: 0 | CL481: 0.16235194 | CM481: 0 | CN481: -0.20356174 | CO481: 0 | CP481: -0.069129317 | CQ481: 0 | CR481: -0.13611795 | CS481: 0 | CT481: -0.16687548 | CU481: 0 | CV481: -0.031580594 | CW481: 0 | CX481: -0.13454032 | CY481: 0 | CZ481: -0.17900507 | DA481: 0 | DB481: -0.11935894 | DC481: 0 | DD481: -0.10630694 | DE481: 0 | DF481: 0.093209524 | DG481: 0 | DH481: 0.25409069 | DI481: 0 | DJ481: 0.27190132 | DK481: 0 | DL481: -0.060204676 | DM481: 0 | DN481: 0.14668686 | DO481: 0 | DP481: -0.030329249 | DQ481: 0 | DR481: -0.058079294 | DS481: 0 | DT481: -0.070138882

Sheet ZC_1
A1: ZC_1 | B1: 1.0016623 | C1: 1.001471 | D1: 1.0012205 | E1: 0.99851264 | F1: 0.99580476 | G1: 0.98416337 | H1: 0.97252197 | I1: 0.97048214 | J1: 0.96844231 | K1: 0.96594474 | L1: 0.96344717 | M1: 0.96278986 | N1: 0.96213255 | O1: 0.96724475 | P1: 0.97235696 | Q1: 0.97468001 | R1: 0.97700306 | S1: 0.98337115 | T1: 0.98973925 | U1: 0.98955314 | V1: 0.98936704 | W1: 0.98543799 | X1: 0.98150894 | Y1: 0.98505906 | Z1: 0.98860919 | AA1: 0.9900223 | AB1: 0.99143541 | AC1: 0.99366715 | AD1: 0.99589889 | AE1: 0.98893635 | AF1: 0.98197381 | AG1: 0.98564249 | AH1: 0.98931117 | AI1: 0.98980808 | AJ1: 0.990305 | AK1: 0.98569922 | AL1: 0.98109345 | AM1: 0.97774894 | AN1: 0.97440442 | AO1: 0.97067967 | AP1: 0.96695492 | AQ1: 0.97550472 | AR1: 0.98405452 | AS1: 0.9811135 | AT1: 0.97817248 | AU1: 0.97649856 | AV1: 0.97482463 | AW1: 0.97264979 | AX1: 0.97047494 | AY1: 0.97662424 | AZ1: 0.98277353 | BA1: 0.97284214 | BB1: 0.96291075 | BC1: 0.95397943 | BD1: 0.94504811 | BE1: 0.94743782 | BF1: 0.94982753 | BG1: 0.94874264 | BH1: 0.94765775 | BI1: 0.94668339 | BJ1: 0.94570904 | BK1: 0.94840809 | BL1: 0.95110714 | BM1: 0.94960836 | BN1: 0.94810958 | BO1: 0.94964661 | BP1: 0.95118363 | BQ1: 0.9516832 | BR1: 0.95218278 | BS1: 0.95663588 | BT1: 0.96108899 | BU1: 0.96512899 | BV1: 0.969169 | BW1: 0.97653336 | BX1: 0.98389772 | BY1: 0.97858902 | BZ1: 0.97328032 | CA1: 0.97107809 | CB1: 0.96887585 | CC1: 0.96362124 | CD1: 0.95836663 | CE1: 0.95991775 | CF1: 0.96146888 | CG1: 0.96568574 | CH1: 0.9699026 | CI1: 0.96755645 | CJ1: 0.9652103 | CK1: 0.96763562 | CL1: 0.97006093 | CM1: 0.97400524 | CN1: 0.97794954 | CO1: 0.98058792 | CP1: 0.9832263 | CQ1: 0.97580792 | CR1: 0.96838955 | CS1: 0.96520592 | CT1: 0.96202229 | CU1: 0.95743814 | CV1: 0.95285398 | CW1: 0.95126902 | CX1: 0.94968406 | CY1: 0.94898597 | CZ1: 0.94828789 | DA1: 0.95384332 | DB1: 0.95939875 | DC1: 0.9630709 | DD1: 0.96674305 | DE1: 0.9622728 | DF1: 0.95780256 | DG1: 0.95788687 | DH1: 0.95797119 | DI1: 0.96115034 | DJ1: 0.96432949 | DK1: 0.95592877 | DL1: 0.94752805 | DM1: 0.94727171 | DN1: 0.94701537 | DO1: 0.94091323 | DP1: 0.93481108 | DQ1: 0.94011401 | DR1: 0.94541693
A2: ZC_1 | B2: 1.0016623 | C2: 0.99623495 | D2: 0.99074842 | E2: 0.98527207 | F2: 0.97979572 | G2: 0.98325853 | H2: 0.98672135 | I2: 0.98207878 | J2: 0.9774362 | K2: 0.96943093 | L2: 0.96142565 | M2: 0.9663443 | N2: 0.97126294 | O2: 0.96786698 | P2: 0.96447103 | Q2: 0.95488786 | R2: 0.9453047 | S2: 0.94259288 | T2: 0.93988107 | U2: 0.93440586 | V2: 0.92893066 | W2: 0.93344566 | X2: 0.93796066 | Y2: 0.93057544 | Z2: 0.92319022 | AA2: 0.92487391 | AB2: 0.92655761 | AC2: 0.93024194 | AD2: 0.93392628 | AE2: 0.93528943 | AF2: 0.93665258 | AG2: 0.93106771 | AH2: 0.92548285 | AI2: 0.91827168 | AJ2: 0.9110605 | AK2: 0.91030275 | AL2: 0.909545 | AM2: 0.90486718 | AN2: 0.90018935 | AO2: 0.89757419 | AP2: 0.89495903 | AQ2: 0.88936491 | AR2: 0.88377078 | AS2: 0.87862747 | AT2: 0.87348416 | AU2: 0.8740502 | AV2: 0.87461623 | AW2: 0.87706592 | AX2: 0.8795156 | AY2: 0.88242674 | AZ2: 0.88533788 | BA2: 0.87822138 | BB2: 0.87110488 | BC2: 0.87723682 | BD2: 0.88336877 | BE2: 0.88447014 | BF2: 0.88557152 | BG2: 0.88270247 | BH2: 0.87983342 | BI2: 0.88181413 | BJ2: 0.88379485 | BK2: 0.88598222 | BL2: 0.88816958 | BM2: 0.88505798 | BN2: 0.88194639 | BO2: 0.87956678 | BP2: 0.87718718 | BQ2: 0.87536883 | BR2: 0.87355048 | BS2: 0.86588865 | BT2: 0.85822683 | BU2: 0.85857253 | BV2: 0.85891824 | BW2: 0.861713 | BX2: 0.86450777 | BY2: 0.86527462 | BZ2: 0.86604147 | CA2: 0.8652417 | CB2: 0.86444193 | CC2: 0.86053996 | CD2: 0.856638 | CE2: 0.85743897 | CF2: 0.85823994 | CG2: 0.85669816 | CH2: 0.85515639 | CI2: 0.86131012 | CJ2: 0.86746384 | CK2: 0.86934372 | CL2: 0.8712236 | CM2: 0.86966895 | CN2: 0.86811429 | CO2: 0.86813821 | CP2: 0.86816213 | CQ2: 0.86577051 | CR2: 0.86337888 | CS2: 0.86514056 | CT2: 0.86690223 | CU2: 0.86589894 | CV2: 0.86489564 | CW2: 0.86839022 | CX2: 0.87188481 | CY2: 0.8671568 | CZ2: 0.86242879 | DA2: 0.86126256 | DB2: 0.86009634 | DC2: 0.86760737 | DD2: 0.8751184 | DE2: 0.87877884 | DF2: 0.88243929 | DG2: 0.87692371 | DH2: 0.87140814 | DI2: 0.87162217 | DJ2: 0.8718362 | DK2: 0.87449576 | DL2: 0.87715531 | DM2: 0.87645957 | DN2: 0.87576383 | DO2: 0.87377243 | DP2: 0.87178103 | DQ2: 0.87333473 | DR2: 0.87488843
A3: ZC_1 | B3: 1.0016623 | C3: 1.0018048 | D3: 1.0018881 | E3: 1.0040796 | F3: 1.0062711 | G3: 1.0079076 | H3: 1.0095442 | I3: 1.0109328 | J3: 1.0123214 | K3: 1.0083291 | L3: 1.0043369 | M3: 1.0081107 | N3: 1.0118845 | O3: 1.0119777 | P3: 1.0120709 | Q3: 1.0076486 | R3: 1.0032263 | S3: 0.99402483 | T3: 0.9848234 | U3: 0.98404036 | V3: 0.98325733 | W3: 0.98505011 | X3: 0.98684289 | Y3: 0.98114827 | Z3: 0.97545366 | AA3: 0.96989027 | AB3: 0.96432688 | AC3: 0.96257573 | AD3: 0.96082458 | AE3: 0.9574612 | AF3: 0.95409783 | AG3: 0.95524551 | AH3: 0.95639319 | AI3: 0.95665306 | AJ3: 0.95691293 | AK3: 0.95479441 | AL3: 0.95267588 | AM3: 0.95040236 | AN3: 0.94812885 | AO3: 0.94951344 | AP3: 0.95089803 | AQ3: 0.94375592 | AR3: 0.9366138 | AS3: 0.93354118 | AT3: 0.93046855 | AU3: 0.93407348 | AV3: 0.93767842 | AW3: 0.94021545 | AX3: 0.94275248 | AY3: 0.94382527 | AZ3: 0.94489806 | BA3: 0.94789383 | BB3: 0.9508896 | BC3: 0.95481552 | BD3: 0.95874144 | BE3: 0.95565608 | BF3: 0.95257073 | BG3: 0.94842792 | BH3: 0.94428511 | BI3: 0.94281526 | BJ3: 0.9413454 | BK3: 0.94289453 | BL3: 0.94444366 | BM3: 0.94672836 | BN3: 0.94901307 | BO3: 0.94504608 | BP3: 0.9410791 | BQ3: 0.93904241 | BR3: 0.93700572 | BS3: 0.94309199 | BT3: 0.94917826 | BU3: 0.95441923 | BV3: 0.95966019 | BW3: 0.95611656 | BX3: 0.95257293 | BY3: 0.94414675 | BZ3: 0.93572058 | CA3: 0.93706575 | CB3: 0.93841093 | CC3: 0.9368234 | CD3: 0.93523588 | CE3: 0.9257569 | CF3: 0.91627793 | CG3: 0.92250721 | CH3: 0.92873648 | CI3: 0.93182456 | CJ3: 0.93491264 | CK3: 0.93366937 | CL3: 0.93242611 | CM3: 0.93169507 | CN3: 0.93096403 | CO3: 0.92937812 | CP3: 0.92779222 | CQ3: 0.92451397 | CR3: 0.92123572 | CS3: 0.9169265 | CT3: 0.91261729 | CU3: 0.90901452 | CV3: 0.90541176 | CW3: 0.90517669 | CX3: 0.90494163 | CY3: 0.90412984 | CZ3: 0.90331804 | DA3: 0.90105149 | DB3: 0.89878494 | DC3: 0.89717345 | DD3: 0.89556196 | DE3: 0.8954363 | DF3: 0.89531065 | DG3: 0.90269176 | DH3: 0.91007288 | DI3: 0.90921751 | DJ3: 0.90836214 | DK3: 0.90223642 | DL3: 0.8961107 | DM3: 0.89099944 | DN3: 0.88588818 | DO3: 0.88215036 | DP3: 0.87841253 | DQ3: 0.88102971 | DR3: 0.88364689
A4: ZC_1 | B4: 1.0016623 | C4: 0.99825139 | D4: 0.9947813 | E4: 0.99785101 | F4: 1.0009207 | G4: 0.99722347 | H4: 0.99352622 | I4: 0.99272509 | J4: 0.99192396 | K4: 0.99515614 | L4: 0.99838831 | M4: 0.9936683 | N4: 0.98894829 | O4: 0.98468439 | P4: 0.98042049 | Q4: 0.97859653 | R4: 0.97677257 | S4: 0.97708944 | T4: 0.97740632 | U4: 0.97691606 | V4: 0.97642579 | W4: 0.97952596 | X4: 0.98262612 | Y4: 0.98109667 | Z4: 0.97956722 | AA4: 0.97340108 | AB4: 0.96723493 | AC4: 0.96497574 | AD4: 0.96271656 | AE4: 0.96772734 | AF4: 0.97273813 | AG4: 0.96299384 | AH4: 0.95324954 | AI4: 0.95292249 | AJ4: 0.95259543 | AK4: 0.9492512 | AL4: 0.94590697 | AM4: 0.94247485 | AN4: 0.93904274 | AO4: 0.93818275 | AP4: 0.93732276 | AQ4: 0.93034044 | AR4: 0.92335811 | AS4: 0.92032217 | AT4: 0.91728623 | AU4: 0.90960013 | AV4: 0.90191403 | AW4: 0.8993561 | AX4: 0.89679817 | AY4: 0.89503496 | AZ4: 0.89327175 | BA4: 0.89870665 | BB4: 0.90414156 | BC4: 0.90851368 | BD4: 0.91288579 | BE4: 0.91182183 | BF4: 0.91075786 | BG4: 0.91091193 | BH4: 0.91106599 | BI4: 0.90980018 | BJ4: 0.90853437 | BK4: 0.90391856 | BL4: 0.89930275 | BM4: 0.8994559 | BN4: 0.89960906 | BO4: 0.89446637 | BP4: 0.88932368 | BQ4: 0.88781592 | BR4: 0.88630816 | BS4: 0.88547961 | BT4: 0.88465106 | BU4: 0.88734689 | BV4: 0.89004273 | BW4: 0.8948127 | BX4: 0.89958268 | BY4: 0.90802836 | BZ4: 0.91647403 | CA4: 0.91781024 | CB4: 0.91914645 | CC4: 0.91921655 | CD4: 0.91928665 | CE4: 0.92358317 | CF4: 0.9278797 | CG4: 0.93007858 | CH4: 0.93227747 | CI4: 0.9384056 | CJ4: 0.94453373 | CK4: 0.94286084 | CL4: 0.94118796 | CM4: 0.93808469 | CN4: 0.93498143 | CO4: 0.9388523 | CP4: 0.94272316 | CQ4: 0.93946236 | CR4: 0.93620155 | CS4: 0.93453454 | CT4: 0.93286753 | CU4: 0.93518815 | CV4: 0.93750877 | CW4: 0.93618613 | CX4: 0.93486349 | CY4: 0.93398784 | CZ4: 0.93311218 | DA4: 0.93111836 | DB4: 0.92912453 | DC4: 0.93072842 | DD4: 0.9323323 | DE4: 0.93191275 | DF4: 0.93149321 | DG4: 0.93101254 | DH4: 0.93053188 | DI4: 0.93492916 | DJ4: 0.93932645 | DK4: 0.93927479 | DL4: 0.93922313 | DM4: 0.9356265 | DN4: 0.93202987 | DO4: 0.92850695 | DP4: 0.92498402 | DQ4: 0.92152973 | DR4: 0.91807545
A5: ZC_1 | B5: 1.0016623 | C5: 0.99792522 | D5: 0.99412896 | E5: 0.99848306 | F5: 1.0028372 | G5: 1.0116264 | H5: 1.0204156 | I5: 1.0126768 | J5: 1.0049379 | K5: 1.0020592 | L5: 0.99918041 | M5: 0.99234271 | N5: 0.985505 | O5: 0.98092868 | P5: 0.97635235 | Q5: 0.96786698 | R5: 0.9593816 | S5: 0.95404565 | T5: 0.9487097 | U5: 0.94572949 | V5: 0.94274928 | W5: 0.94072546 | X5: 0.93870165 | Y5: 0.9357966 | Z5: 0.93289155 | AA5: 0.93269458 | AB5: 0.93249762 | AC5: 0.93244863 | AD5: 0.93239964 | AE5: 0.93707974 | AF5: 0.94175983 | AG5: 0.94539114 | AH5: 0.94902244 | AI5: 0.94563838 | AJ5: 0.94225432 | AK5: 0.94231479 | AL5: 0.94237527 | AM5: 0.94120737 | AN5: 0.94003948 | AO5: 0.93497956 | AP5: 0.92991965 | AQ5: 0.93038653 | AR5: 0.93085341 | AS5: 0.92712889 | AT5: 0.92340437 | AU5: 0.91879317 | AV5: 0.91418198 | AW5: 0.90654914 | AX5: 0.89891631 | AY5: 0.89623104 | AZ5: 0.89354576 | BA5: 0.89063212 | BB5: 0.88771849 | BC5: 0.88943519 | BD5: 0.8911519 | BE5: 0.88655575 | BF5: 0.8819596 | BG5: 0.88428751 | BH5: 0.88661542 | BI5: 0.88264942 | BJ5: 0.87868341 | BK5: 0.87731937 | BL5: 0.87595533 | BM5: 0.87123517 | BN5: 0.866515 | BO5: 0.86539024 | BP5: 0.86426549 | BQ5: 0.85889327 | BR5: 0.85352106 | BS5: 0.85940524 | BT5: 0.86528943 | BU5: 0.86421009 | BV5: 0.86313075 | BW5: 0.86106256 | BX5: 0.85899437 | BY5: 0.85635707 | BZ5: 0.85371977 | CA5: 0.8521458 | CB5: 0.85057183 | CC5: 0.85114396 | CD5: 0.85171609 | CE5: 0.85223365 | CF5: 0.8527512 | CG5: 0.85528133 | CH5: 0.85781145 | CI5: 0.85873281 | CJ5: 0.85965416 | CK5: 0.85689267 | CL5: 0.85413118 | CM5: 0.85401885 | CN5: 0.85390651 | CO5: 0.84933032 | CP5: 0.84475412 | CQ5: 0.83649193 | CR5: 0.82822975 | CS5: 0.82503379 | CT5: 0.82183784 | CU5: 0.8219082 | CV5: 0.82197855 | CW5: 0.82279619 | CX5: 0.82361384 | CY5: 0.82330576 | CZ5: 0.82299767 | DA5: 0.82415416 | DB5: 0.82531064 | DC5: 0.82270818 | DD5: 0.82010572 | DE5: 0.81653918 | DF5: 0.81297263 | DG5: 0.81280591 | DH5: 0.81263918 | DI5: 0.81203987 | DJ5: 0.81144057 | DK5: 0.80848105 | DL5: 0.80552152 | DM5: 0.80568137 | DN5: 0.80584122 | DO5: 0.81041277 | DP5: 0.81498433 | DQ5: 0.81603114 | DR5: 0.81707796
A6: ZC_1 | B6: 1.0016623 | C6: 1.0010891 | D6: 1.0004567 | E6: 1.0018532 | F6: 1.0032497 | G6: 1.012654 | H6: 1.0220582 | I6: 1.0214895 | J6: 1.0209209 | K6: 1.0201755 | L6: 1.0194302 | M6: 1.016891 | N6: 1.0143519 | O6: 1.0058968 | P6: 0.9974417 | Q6: 0.99264543 | R6: 0.98784917 | S6: 0.97962737 | T6: 0.97140556 | U6: 0.96997317 | V6: 0.96854077 | W6: 0.9711603 | X6: 0.97377984 | Y6: 0.96893777 | Z6: 0.96409571 | AA6: 0.96238799 | AB6: 0.96068027 | AC6: 0.95899111 | AD6: 0.95730195 | AE6: 0.96470424 | AF6: 0.97210653 | AG6: 0.96852158 | AH6: 0.96493662 | AI6: 0.96296299 | AJ6: 0.96098935 | AK6: 0.9633961 | AL6: 0.96580284 | AM6: 0.96589318 | AN6: 0.96598352 | AO6: 0.9659902 | AP6: 0.96599688 | AQ6: 0.95450842 | AR6: 0.94301997 | AS6: 0.94256722 | AT6: 0.94211447 | AU6: 0.9413933 | AV6: 0.94067212 | AW6: 0.93991918 | AX6: 0.93916624 | AY6: 0.93134169 | AZ6: 0.92351714 | BA6: 0.93081594 | BB6: 0.93811473 | BC6: 0.94496932 | BD6: 0.95182391 | BE6: 0.94745003 | BF6: 0.94307615 | BG6: 0.94247541 | BH6: 0.94187468 | BI6: 0.94120756 | BJ6: 0.94054044 | BK6: 0.93598952 | BL6: 0.93143859 | BM6: 0.9313595 | BN6: 0.93128042 | BO6: 0.9285911 | BP6: 0.92590178 | BQ6: 0.92365659 | BR6: 0.92141141 | BS6: 0.91575535 | BT6: 0.91009928 | BU6: 0.90498131 | BV6: 0.89986333 | BW6: 0.89186653 | BX6: 0.88386974 | BY6: 0.88712193 | BZ6: 0.89037412 | CA6: 0.89156143 | CB6: 0.89274874 | CC6: 0.8957618 | CD6: 0.89877487 | CE6: 0.8965864 | CF6: 0.89439794 | CG6: 0.88908461 | CH6: 0.88377129 | CI6: 0.88451562 | CJ6: 0.88525996 | CK6: 0.88207779 | CL6: 0.87889561 | CM6: 0.87403661 | CN6: 0.86917762 | CO6: 0.86597138 | CP6: 0.86276515 | CQ6: 0.86769773 | CR6: 0.87263032 | CS6: 0.87470056 | CT6: 0.87677081 | CU6: 0.87977265 | CV6: 0.88277449 | CW6: 0.88305075 | CX6: 0.88332701 | CY6: 0.88235355 | CZ6: 0.88138008 | DA6: 0.87560689 | DB6: 0.86983369 | DC6: 0.86544158 | DD6: 0.86104947 | DE6: 0.863524 | DF6: 0.86599852 | DG6: 0.86536323 | DH6: 0.86472794 | DI6: 0.86038497 | DJ6: 0.85604199 | DK6: 0.86263329 | DL6: 0.86922458 | DM6: 0.8684899 | DN6: 0.86775522 | DO6: 0.87193789 | DP6: 0.87612057 | DQ6: 0.87027975 | DR6: 0.86443893
A7: ZC_1 | B7: 1.0016623 | C7: 1.0063764 | D7: 1.0110314 | E7: 1.0153367 | F7: 1.019642 | G7: 1.0134961 | H7: 1.0073503 | I7: 1.0094386 | J7: 1.0115269 | K7: 1.0165503 | L7: 1.0215736 | M7: 1.013195 | N7: 1.0048165 | O7: 1.0052068 | P7: 1.0055972 | Q7: 1.0132857 | R7: 1.0209741 | S7: 1.0219551 | T7: 1.022936 | U7: 1.0272451 | V7: 1.0315542 | W7: 1.0252727 | X7: 1.0189912 | Y7: 1.0257022 | Z7: 1.0324133 | AA7: 1.0301803 | AB7: 1.0279473 | AC7: 1.0243865 | AD7: 1.0208257 | AE7: 1.0199845 | AF7: 1.0191433 | AG7: 1.0253146 | AH7: 1.031486 | AI7: 1.0380313 | AJ7: 1.0445767 | AK7: 1.0431767 | AL7: 1.0417768 | AM7: 1.0436998 | AN7: 1.0456229 | AO7: 1.0446652 | AP7: 1.0437075 | AQ7: 1.0468672 | AR7: 1.0500269 | AS7: 1.0525276 | AT7: 1.0550282 | AU7: 1.0517385 | AV7: 1.0484488 | AW7: 1.0423717 | AX7: 1.0362946 | AY7: 1.0307246 | AZ7: 1.0251546 | BA7: 1.0310687 | BB7: 1.0369828 | BC7: 1.0276329 | BD7: 1.018283 | BE7: 1.0148938 | BF7: 1.0115046 | BG7: 1.0129931 | BH7: 1.0144816 | BI7: 1.0104558 | BJ7: 1.0064299 | BK7: 1.0019361 | BL7: 0.99744228 | BM7: 0.99929345 | BN7: 1.0011446 | BO7: 1.0025761 | BP7: 1.0040076 | BQ7: 1.0041798 | BR7: 1.0043519 | BS7: 1.0117652 | BT7: 1.0191786 | BU7: 1.0172742 | BV7: 1.0153698 | BW7: 1.0106517 | BX7: 1.0059336 | BY7: 1.0032798 | BZ7: 1.000626 | CA7: 1.0006142 | CB7: 1.0006024 | CC7: 1.0030549 | CD7: 1.0055074 | CE7: 1.0037417 | CF7: 1.001976 | CG7: 1.0021665 | CH7: 1.0023571 | CI7: 0.9936844 | CJ7: 0.9850117 | CK7: 0.9818075 | CL7: 0.9786033 | CM7: 0.97887535 | CN7: 0.9791474 | CO7: 0.9781307 | CP7: 0.97711401 | CQ7: 0.97794011 | CR7: 0.97876622 | CS7: 0.97586995 | CT7: 0.97297369 | CU7: 0.97276238 | CV7: 0.97255108 | CW7: 0.96734917 | CX7: 0.96214727 | CY7: 0.96563657 | CZ7: 0.96912588 | DA7: 0.96969311 | DB7: 0.97026033 | DC7: 0.96073072 | DD7: 0.95120111 | DE7: 0.9455794 | DF7: 0.9399577 | DG7: 0.94529255 | DH7: 0.9506274 | DI7: 0.94874354 | DJ7: 0.94685968 | DK7: 0.94291036 | DL7: 0.93896104 | DM7: 0.93865811 | DN7: 0.93835518 | DO7: 0.93890977 | DP7: 0.93946436 | DQ7: 0.93679471 | DR7: 0.93412506
A8: ZC_1 | B8: 1.0016623 | C8: 1.0007558 | D8: 0.99979007 | E8: 0.99630247 | F8: 0.99281486 | G8: 0.98869595 | H8: 0.98457705 | I8: 0.98062304 | J8: 0.97666903 | K8: 0.9772975 | L8: 0.97792596 | M8: 0.9712023 | N8: 0.96447863 | O8: 0.96139022 | P8: 0.95830181 | Q8: 0.96016485 | R8: 0.9620279 | S8: 0.96914117 | T8: 0.97625444 | U8: 0.97540674 | V8: 0.97455904 | W8: 0.97153776 | X8: 0.96851649 | Y8: 0.97280728 | Z8: 0.97709806 | AA8: 0.98239217 | AB8: 0.98768628 | AC8: 0.98996697 | AD8: 0.99224767 | AE8: 0.99637817 | AF8: 1.0005087 | AG8: 0.99932866 | AH8: 0.99814865 | AI8: 0.99633616 | AJ8: 0.99452367 | AK8: 0.99456783 | AL8: 0.99461198 | AM8: 0.99368295 | AN8: 0.99275391 | AO8: 0.98753131 | AP8: 0.98230872 | AQ8: 0.98654695 | AR8: 0.99078517 | AS8: 0.99060033 | AT8: 0.99041548 | AU8: 0.9841762 | AV8: 0.97793693 | AW8: 0.97236009 | AX8: 0.96678325 | AY8: 0.96365941 | AZ8: 0.96053558 | BA8: 0.95525498 | BB8: 0.94997439 | BC8: 0.94410189 | BD8: 0.93822939 | BE8: 0.93929484 | BF8: 0.94036028 | BG8: 0.9427995 | BH8: 0.94523871 | BI8: 0.94506953 | BJ8: 0.94490035 | BK8: 0.94145533 | BL8: 0.93801031 | BM8: 0.93420206 | BN8: 0.93039381 | BO8: 0.93311858 | BP8: 0.93584335 | BQ8: 0.93608962 | BR8: 0.93633588 | BS8: 0.92892776 | BT8: 0.92151963 | BU8: 0.91514963 | BV8: 0.90877964 | BW8: 0.91085745 | BX8: 0.91293527 | BY8: 0.91952446 | BZ8: 0.92611366 | CA8: 0.92392246 | CB8: 0.92173127 | CC8: 0.92136755 | CD8: 0.92100384 | CE8: 0.92975681 | CF8: 0.93850977 | CG8: 0.93072705 | CH8: 0.92294433 | CI8: 0.91844643 | CJ8: 0.91394853 | CK8: 0.91415918 | CL8: 0.91436982 | CM8: 0.9137073 | CN8: 0.91304479 | CO8: 0.91367938 | CP8: 0.91431397 | CQ8: 0.91580511 | CR8: 0.91729625 | CS8: 0.92076575 | CT8: 0.92423525 | CU8: 0.9266329 | CV8: 0.92903055 | CW8: 0.92801566 | CX8: 0.92700077 | CY8: 0.92612928 | CZ8: 0.92525779 | DA8: 0.92687641 | DB8: 0.92849504 | DC8: 0.92899124 | DD8: 0.92948744 | DE8: 0.92796595 | DF8: 0.92644447 | DG8: 0.91834208 | DH8: 0.91023969 | DI8: 0.9095127 | DJ8: 0.90878571 | DK8: 0.91394248 | DL8: 0.91909925 | DM8: 0.92336524 | DN8: 0.92763122 | DO8: 0.93000159 | DP8: 0.93237196 | DQ8: 0.92861912 | DR8: 0.92486628
A9: ZC_1 | B9: 1.0016623 | C9: 1.0043271 | D9: 1.0069326 | E9: 1.0025273 | F9: 0.99812187 | G9: 0.99928631 | H9: 1.0004507 | I9: 0.99860177 | J9: 0.9967528 | K9: 0.9902527 | L9: 0.9837526 | M9: 0.98529997 | N9: 0.98684734 | O9: 0.98804276 | P9: 0.98923818 | Q9: 0.98866023 | R9: 0.98808227 | S9: 0.98587252 | T9: 0.98366277 | U9: 0.98252014 | V9: 0.98137752 | W9: 0.97702511 | X9: 0.97267271 | Y9: 0.97283379 | Z9: 0.97299487 | AA9: 0.9788558 | AB9: 0.98471674 | AC9: 0.98750719 | AD9: 0.99029765 | AE9: 0.98581693 | AF9: 0.98133621 | AG9: 0.99138829 | AH9: 1.0014404 | AI9: 1.0002358 | AJ9: 0.99903121 | AK9: 1.0003803 | AL9: 1.0017294 | AM9: 1.0020446 | AN9: 1.0023597 | AO9: 0.99944762 | AP9: 0.99653552 | AQ9: 1.0007722 | AR9: 1.0050088 | AS9: 1.0048288 | AT9: 1.0046487 | AU9: 1.0106823 | AV9: 1.0167159 | AW9: 1.0165198 | AX9: 1.0163238 | AY9: 1.0161866 | AZ9: 1.0160494 | BA9: 1.0075708 | BB9: 0.99909218 | BC9: 0.99222513 | BD9: 0.98535808 | BE9: 0.98444514 | BF9: 0.9835322 | BG9: 0.98161801 | BH9: 0.97970383 | BI9: 0.97936427 | BJ9: 0.97902471 | BK9: 0.98205944 | BL9: 0.98509416 | BM9: 0.9832913 | BN9: 0.98148844 | BO9: 0.98589724 | BP9: 0.99030604 | BQ9: 0.99010055 | BR9: 0.98989507 | BS9: 0.98931556 | BT9: 0.98873606 | BU9: 0.98429936 | BV9: 0.97986267 | BW9: 0.97328736 | BX9: 0.96671206 | BY9: 0.95613735 | BZ9: 0.94556264 | CA9: 0.94330628 | CB9: 0.94104992 | CC9: 0.93901639 | CD9: 0.93698286 | CE9: 0.93187898 | CF9: 0.92677509 | CG9: 0.92310694 | CH9: 0.91943879 | CI9: 0.91203889 | CJ9: 0.90463898 | CK9: 0.90524831 | CL9: 0.90585763 | CM9: 0.90748963 | CN9: 0.90912164 | CO9: 0.90447731 | CP9: 0.89983297 | CQ9: 0.9012328 | CR9: 0.90263264 | CS9: 0.90340251 | CT9: 0.90417239 | CU9: 0.9006981 | CV9: 0.8972238 | CW9: 0.89727718 | CX9: 0.89733057 | CY9: 0.8965225 | CZ9: 0.89571444 | DA9: 0.89694522 | DB9: 0.898176 | DC9: 0.89550265 | DD9: 0.8928293 | DE9: 0.89164366 | DF9: 0.89045802 | DG9: 0.89034243 | DH9: 0.89022684 | DI9: 0.8845275 | DJ9: 0.87882817 | DK9: 0.87786936 | DL9: 0.87691055 | DM9: 0.87930892 | DN9: 0.88170729 | DO9: 0.88356789 | DP9: 0.8854285 | DQ9: 0.88780578 | DR9: 0.89018306
A10: ZC_1 | B10: 1.0016623 | C10: 1.0046574 | D10: 1.0075934 | E10: 1.0019039 | F10: 0.99621444 | G10: 0.98515098 | H10: 0.97408751 | I10: 0.97896616 | J10: 0.98384481 | K10: 0.98340877 | L10: 0.98297273 | M10: 0.98663402 | N10: 0.99029532 | O10: 0.99182766 | P10: 0.99336001 | Q10: 0.99967676 | R10: 1.0059935 | S10: 1.0097051 | T10: 1.0134166 | U10: 1.0149253 | V10: 1.0164339 | W10: 1.0173103 | X10: 1.0181868 | Y10: 1.0199319 | Z10: 1.021677 | AA10: 1.0215382 | AB10: 1.0213993 | AC10: 1.0219482 | AD10: 1.0224971 | AE10: 1.0180567 | AF10: 1.0136163 | AG10: 1.0097586 | AH10: 1.005901 | AI10: 1.0079482 | AJ10: 1.0099954 | AK10: 1.0077395 | AL10: 1.0054836 | AM10: 1.0033902 | AN10: 1.0012969 | AO10: 1.0028829 | AP10: 1.004469 | AQ10: 1.0006927 | AR10: 0.99691644 | AS10: 0.99745437 | AT10: 0.9979923 | AU10: 1.0005322 | AV10: 1.003072 | AW10: 1.0085005 | AX10: 1.013929 | AY10: 1.0148334 | AZ10: 1.0157378 | BA10: 1.0166567 | BB10: 1.0175757 | BC10: 1.0134826 | BD10: 1.0093895 | BE10: 1.0125183 | BF10: 1.0156471 | BG10: 1.0111843 | BH10: 1.0067215 | BI10: 1.009503 | BJ10: 1.0122845 | BK10: 1.0118175 | BL10: 1.0113505 | BM10: 1.0151621 | BN10: 1.0189736 | BO10: 1.0189961 | BP10: 1.0190186 | BQ10: 1.0234697 | BR10: 1.0279208 | BS10: 1.0193904 | BT10: 1.0108599 | BU10: 1.0106371 | BV10: 1.0104143 | BW10: 1.0114022 | BX10: 1.0123901 | BY10: 1.0137291 | BZ10: 1.015068 | CA10: 1.0159935 | CB10: 1.0169191 | CC10: 1.0141185 | CD10: 1.011318 | CE10: 1.0098716 | CF10: 1.0084252 | CG10: 1.0038399 | CH10: 0.99925463 | CI10: 0.99660742 | CJ10: 0.99396022 | CK10: 0.9960734 | CL10: 0.99818659 | CM10: 0.9968128 | CN10: 0.99543901 | CO10: 0.99981435 | CP10: 1.0041897 | CQ10: 1.0122468 | CR10: 1.0203039 | CS10: 1.0233147 | CT10: 1.0263254 | CU10: 1.0248276 | CV10: 1.0233299 | CW10: 1.0209337 | CX10: 1.0185375 | CY10: 1.0170479 | CZ10: 1.0155582 | DA10: 1.0133568 | DB10: 1.0111555 | DC10: 1.0130816 | DD10: 1.0150077 | DE10: 1.0176413 | DF10: 1.0202749 | DG10: 1.0198252 | DH10: 1.0193755 | DI10: 1.018355 | DJ10: 1.0173346 | DK10: 1.019898 | DL10: 1.0224614 | DM10: 1.0211187 | DN10: 1.019776 | DO10: 1.0123561 | DP10: 1.0049361 | DQ10: 1.0025765 | DR10: 1.0002169
B11: =AVERAGE(B1:B10) -> 1.0016623 | C11: =AVERAGE(C1:C10) -> 1.0012893 | D11: =AVERAGE(D1:D10) -> 1.0008572 | E11: =AVERAGE(E1:E10) -> 1.0002122 | F11: =AVERAGE(F1:F10) -> 0.99956723 | G11: =AVERAGE(G1:G10) -> 0.99834627 | H11: =AVERAGE(H1:H10) -> 0.99712531 | I11: =AVERAGE(I1:I10) -> 0.99580147 | ... DR11: =AVERAGE(DR1:DR10) -> 0.90529359

Sheet ZC_5
A1: ZC_5 | B1: 0.99445428 | C1: 0.99034668 | D1: 0.98597933 | E1: 0.96997465 | F1: 0.95396997 | G1: 0.90104653 | H1: 0.84812309 | I1: 0.83878987 | J1: 0.82945664 | K1: 0.82001548 | L1: 0.81057432 | M1: 0.80915228 | N1: 0.80773025 | O1: 0.83107145 | P1: 0.85441265 | Q1: 0.86584529 | R1: 0.87727794 | S1: 0.90709037 | T1: 0.9369028 | U1: 0.93786637 | V1: 0.93882993 | W1: 0.92293179 | X1: 0.90703365 | Y1: 0.92613228 | Z1: 0.9452309 | AA1: 0.95230618 | AB1: 0.95938145 | AC1: 0.96758922 | AD1: 0.975797 | AE1: 0.93920134 | AF1: 0.90260569 | AG1: 0.91415884 | AH1: 0.925712 | AI1: 0.9248988 | AJ1: 0.9240856 | AK1: 0.90111409 | AL1: 0.87814258 | AM1: 0.86366558 | AN1: 0.84918857 | AO1: 0.83465593 | AP1: 0.82012328 | AQ1: 0.85733591 | AR1: 0.89454854 | AS1: 0.88319111 | AT1: 0.87183368 | AU1: 0.86461322 | AV1: 0.85739275 | AW1: 0.8494495 | AX1: 0.84150626 | AY1: 0.8680097 | AZ1: 0.89451315 | BA1: 0.852787 | BB1: 0.81106084 | BC1: 0.77593108 | BD1: 0.74080132 | BE1: 0.75035046 | BF1: 0.7598996 | BG1: 0.75576727 | BH1: 0.75163493 | BI1: 0.74783695 | BJ1: 0.74403896 | BK1: 0.75502946 | BL1: 0.76601997 | BM1: 0.76028249 | BN1: 0.75454501 | BO1: 0.76001101 | BP1: 0.765477 | BQ1: 0.76789031 | BR1: 0.77030361 | BS1: 0.78827519 | BT1: 0.80624676 | BU1: 0.82279704 | BV1: 0.83934732 | BW1: 0.87126059 | BX1: 0.90317386 | BY1: 0.88052404 | BZ1: 0.85787421 | CA1: 0.84747168 | CB1: 0.83706915 | CC1: 0.8166011 | CD1: 0.79613305 | CE1: 0.80139816 | CF1: 0.80666327 | CG1: 0.82459916 | CH1: 0.84253505 | CI1: 0.83294485 | CJ1: 0.82335465 | CK1: 0.83305955 | CL1: 0.84276445 | CM1: 0.85996711 | CN1: 0.87716977 | CO1: 0.88805991 | CP1: 0.89895005 | CQ1: 0.86768483 | CR1: 0.83641961 | CS1: 0.82250915 | CT1: 0.8085987 | CU1: 0.790229 | CV1: 0.7718593 | CW1: 0.76548483 | CX1: 0.75911036 | CY1: 0.75739931 | CZ1: 0.75568826 | DA1: 0.77676431 | DB1: 0.79784035 | DC1: 0.81273701 | DD1: 0.82763367 | DE1: 0.81021455 | DF1: 0.79279542 | DG1: 0.79188583 | DH1: 0.79097624 | DI1: 0.80460158 | DJ1: 0.81822691 | DK1: 0.78427913 | DL1: 0.75033135 | DM1: 0.74916299 | DN1: 0.74799462 | DO1: 0.72551641 | DP1: 0.70303819 | DQ1: 0.72269902 | DR1: 0.74235985
A2: ZC_5 | B2: 0.99445428 | C2: 0.96575403 | D2: 0.93679403 | E2: 0.90920423 | F2: 0.88161443 | G2: 0.89586457 | H2: 0.91011471 | I2: 0.88887019 | J2: 0.86762568 | K2: 0.8349781 | L2: 0.80233053 | M2: 0.82402825 | N2: 0.84572598 | O2: 0.83346958 | P2: 0.82121318 | Q2: 0.78419565 | R2: 0.74717812 | S2: 0.73785148 | T2: 0.72852483 | U2: 0.7096697 | V2: 0.69081458 | W2: 0.70904579 | X2: 0.727277 | Y2: 0.70232674 | Z2: 0.67737649 | AA2: 0.68376469 | AB2: 0.69015289 | AC2: 0.70196439 | AD2: 0.71377589 | AE2: 0.71547444 | AF2: 0.71717299 | AG2: 0.69315131 | AH2: 0.66912964 | AI2: 0.64245576 | AJ2: 0.61578189 | AK2: 0.61161794 | AL2: 0.607454 | AM2: 0.59248157 | AN2: 0.57750914 | AO2: 0.57014448 | AP2: 0.56277983 | AQ2: 0.54647933 | AR2: 0.53017882 | AS2: 0.5163637 | AT2: 0.50254858 | AU2: 0.50413321 | AV2: 0.50571784 | AW2: 0.5134833 | AX2: 0.52124875 | AY2: 0.52969915 | AZ2: 0.53814955 | BA2: 0.51809822 | BB2: 0.49804688 | BC2: 0.51571893 | BD2: 0.53339097 | BE2: 0.53688699 | BF2: 0.54038301 | BG2: 0.53201966 | BH2: 0.52365631 | BI2: 0.52940663 | BJ2: 0.53515695 | BK2: 0.54205287 | BL2: 0.54894878 | BM2: 0.53978643 | BN2: 0.53062407 | BO2: 0.52337483 | BP2: 0.51612558 | BQ2: 0.51125773 | BR2: 0.50638987 | BS2: 0.4855633 | BT2: 0.46473672 | BU2: 0.4655302 | BV2: 0.46632367 | BW2: 0.47377392 | BX2: 0.48122416 | BY2: 0.48363582 | BZ2: 0.48604749 | CA2: 0.48327505 | CB2: 0.48050262 | CC2: 0.47080581 | CD2: 0.46110901 | CE2: 0.46261344 | CF2: 0.46411788 | CG2: 0.4603174 | CH2: 0.45651692 | CI2: 0.47309659 | CJ2: 0.48967625 | CK2: 0.49461028 | CL2: 0.4995443 | CM2: 0.49538204 | CN2: 0.49121977 | CO2: 0.49087752 | CP2: 0.49053527 | CQ2: 0.48448292 | CR2: 0.47843057 | CS2: 0.48279944 | CT2: 0.4871683 | CU2: 0.48446162 | CV2: 0.48175494 | CW2: 0.49126795 | CX2: 0.50078096 | CY2: 0.48846698 | CZ2: 0.47615301 | DA2: 0.47246954 | DB2: 0.46878607 | DC2: 0.48927878 | DD2: 0.5097715 | DE2: 0.52090609 | DF2: 0.53204068 | DG2: 0.5154548 | DH2: 0.49886892 | DI2: 0.49988523 | DJ2: 0.50090153 | DK2: 0.50814715 | DL2: 0.51539276 | DM2: 0.51328528 | DN2: 0.51117779 | DO2: 0.50585603 | DP2: 0.50053427 | DQ2: 0.50478292 | DR2: 0.50903157
A3: ZC_5 | B3: 0.99445428 | C3: 0.99194849 | D3: 0.98918297 | E3: 0.99647617 | F3: 1.0037694 | G3: 1.0105097 | H3: 1.0172501 | I3: 1.0231712 | J3: 1.0290923 | K3: 1.0107002 | L3: 0.99230806 | M3: 1.0123336 | N3: 1.0323591 | O3: 1.0352767 | P3: 1.0381943 | Q3: 1.0180853 | R3: 0.9979764 | S3: 0.95622411 | T3: 0.91447182 | U3: 0.91271028 | V3: 0.91094875 | W3: 0.92111274 | X3: 0.93127673 | Y3: 0.90842313 | Z3: 0.88556953 | AA3: 0.86192937 | AB3: 0.83828921 | AC3: 0.82892133 | AD3: 0.81955345 | AE3: 0.80205889 | AF3: 0.78456433 | AG3: 0.78485548 | AH3: 0.78514662 | AI3: 0.78357908 | AJ3: 0.78201154 | AK3: 0.77155328 | AL3: 0.76109501 | AM3: 0.75225013 | AN3: 0.74340525 | AO3: 0.74967161 | AP3: 0.75593797 | AQ3: 0.72964149 | AR3: 0.703345 | AS3: 0.69343659 | AT3: 0.68352819 | AU3: 0.69660508 | AV3: 0.70968197 | AW3: 0.72024241 | AX3: 0.73080285 | AY3: 0.73479317 | AZ3: 0.73878349 | BA3: 0.75087043 | BB3: 0.76295736 | BC3: 0.77874128 | BD3: 0.79452521 | BE3: 0.78258286 | BF3: 0.77064052 | BG3: 0.75467294 | BH3: 0.73870536 | BI3: 0.73309219 | BJ3: 0.72747903 | BK3: 0.73386566 | BL3: 0.7402523 | BM3: 0.74915158 | BN3: 0.75805087 | BO3: 0.74237831 | BP3: 0.72670575 | BQ3: 0.71953389 | BR3: 0.71236203 | BS3: 0.73556595 | BT3: 0.75876987 | BU3: 0.77939579 | BV3: 0.8000217 | BW3: 0.7858035 | BX3: 0.7715853 | BY3: 0.73996189 | BZ3: 0.70833847 | CA3: 0.71243362 | CB3: 0.71652877 | CC3: 0.71170462 | CD3: 0.70688048 | CE3: 0.6725253 | CF3: 0.63817012 | CG3: 0.6601901 | CH3: 0.68221008 | CI3: 0.69359506 | CJ3: 0.70498004 | CK3: 0.70005951 | CL3: 0.69513899 | CM3: 0.69270009 | CN3: 0.69026118 | CO3: 0.68401211 | CP3: 0.67776303 | CQ3: 0.66688958 | CR3: 0.65601612 | CS3: 0.64081028 | CT3: 0.62560443 | CU3: 0.61379817 | CV3: 0.60199191 | CW3: 0.60110077 | CX3: 0.60020962 | CY3: 0.59838527 | CZ3: 0.59656091 | DA3: 0.58864497 | DB3: 0.58072903 | DC3: 0.57556757 | DD3: 0.57040611 | DE3: 0.57064774 | DF3: 0.57088937 | DG3: 0.59356369 | DH3: 0.61623801 | DI3: 0.61394153 | DJ3: 0.61164505 | DK3: 0.59177751 | DL3: 0.57190997 | DM3: 0.55624919 | DN3: 0.54058841 | DO3: 0.5299638 | DP3: 0.51933919 | DQ3: 0.52682812 | DR3: 0.53431704
